<?xml version="1.0" ?>
<!-- =================================================================================== -->
<!-- |    This document was autogenerated by xacro from src/ur3e_robotiq/ur3e_robotiq_description/urdf/ur3e_robotiq.urdf.xacro | -->
<!-- |    EDITING THIS FILE BY HAND IS NOT RECOMMENDED                                 | -->
<!-- =================================================================================== -->
<robot name="ur3e_robotiq">

  <gazebo>
    <plugin filename="libgz_ros2_control-system.so" name="gz_ros2_control::GazeboSimROS2ControlPlugin">
      <parameters>$(find ur3e_robotiq_description)/config/ros2_controllers.yaml</parameters>
    </plugin>
    <plugin filename="gz-sim-sensors-system" name="gz::sim::systems::Sensors">
      <render_engine>ogre2</render_engine>
    </plugin>
  </gazebo>
  
  <!-- <link name="table">
    <visual>
      <origin rpy="1.570796 0 1.570796" xyz="0.715 .9114 -.14"/>
      <geometry>
        <mesh filename="file://$(find ur3e_robotiq_description)/urdf/meshes/visual/table.obj" scale="0.01 0.01 0.01"/>
      </geometry>
    </visual>
    <collision>
      <origin rpy="0 0 0" xyz="0 .3 -0.125"/>
      <geometry>
        <box size="1.5 1.5 0.2"/>
      </geometry>
    </collision>
  </link> -->
  <!-- Joint between table and ur -->
  <!-- <joint name="table_joint" type="fixed">
    <origin rpy="0 0 0" xyz="0 0 0"/>
    <parent link="base_link"/>
    <child link="table"/>
  </joint> -->

  <!-- Joint connecting hand to ur -->
  <joint name="hand_joint" type="fixed">
    <parent link="tool0"/>
    <child link="robotiq_hande_coupler"/>
    <origin rpy="0 0 0" xyz="0 0 0"/>
  </joint>

  <!-- create link fixed to the "world" -->
  <link name="world"/>

  <!-- Robotiq Hand-e -->
  <link name="robotiq_hande_coupler">
    <visual>
      <geometry>
        <mesh filename="file://$(find ur3e_robotiq_description)/urdf/meshes/visual/io_coupler.dae"/>
      </geometry>
    </visual>
    <collision>
      <origin rpy="0 0 0" xyz="0 0 0.00545"/>
      <geometry>
        <cylinder length="0.0169" radius="0.0385"/>
      </geometry>
    </collision>
    <inertial>
      <mass value="0.86387"/>
      <origin rpy="0 0 0" xyz="0 0 0.00545"/>
      <inertia ixx="0.00101" ixy="0.0" ixz="0.0" iyy="0.00101" iyz="0.0" izz="0.000101"/>
    </inertial>
  </link>

  <joint name="robotiq_hande_base_joint" type="fixed">
    <origin rpy="0 0 0" xyz="0 0 0.011"/>
    <parent link="robotiq_hande_coupler"/>
    <child link="robotiq_hande_link"/>
  </joint>

  <link name="robotiq_hande_link">
    <visual>
      <origin rpy="0 0 0" xyz="0 0 0"/>
      <geometry>
        <mesh filename="file://$(find ur3e_robotiq_description)/urdf/meshes/visual/hande.dae" scale="1.0 1.0 1.0"/>
      </geometry>
    </visual>
    <collision>
      <origin rpy="0 0 0" xyz="0 0 0.05345"/>
      <geometry>
        <cylinder length="0.1069" radius="0.0385"/>
      </geometry>
    </collision>
    <inertial>
      <mass value="0.86387"/>
      <origin rpy="0 0 0" xyz="0 0 0.00545"/>
      <inertia ixx="0.00101" ixy="0.0" ixz="0.0" iyy="0.00101" iyz="0.0" izz="0.000101"/>
    </inertial>
  </link>

  <joint name="robotiq_hande_left_finger_joint" type="prismatic">
    <origin rpy="0 0 0" xyz="0 0 0.099"/>
    <parent link="robotiq_hande_link"/>
    <child link="robotiq_hande_left_finger"/>
    <axis xyz="1 0 0"/>
    <limit effort="130" lower="0" upper="0.025" velocity="0.15"/>
  </joint>
  
  <link name="robotiq_hande_left_finger">
    <visual>
      <origin rpy="0 0 0" xyz="0 0 0"/>
      <geometry>
        <mesh filename="file://$(find ur3e_robotiq_description)/urdf/meshes/visual/finger.dae" scale="1.0 1.0 1.0"/>
      </geometry>
    </visual>
    <collision>
      <origin rpy="0 0 0" xyz="0 0 0"/>
      <geometry>
        <mesh filename="file://$(find ur3e_robotiq_description)/urdf/meshes/collision/finger_collision.dae" scale="1.0 1.0 1.0"/>
      </geometry>
    </collision>
    <inertial>
      <origin rpy="0 0 0" xyz="0 0 0"/>
      <mass value="0.03804"/>
      <inertia ixx="1E-9" ixy="0.0" ixz="0.0" iyy="1E-9" iyz="0.0" izz="1E-9"/>
    </inertial>
  </link>

  <joint name="robotiq_hande_right_finger_joint" type="prismatic">
    <origin rpy="0 0 0" xyz="0 0 0.099"/>
    <parent link="robotiq_hande_link"/>
    <child link="robotiq_hande_right_finger"/>
    <axis xyz="-1 0 0"/>
    <limit effort="130" lower="0" upper="0.025" velocity="0.15"/>
    <mimic joint="robotiq_hande_left_finger_joint" multiplier="1" offset="0"/>
  </joint>

  <link name="robotiq_hande_right_finger">
    <visual>
      <origin rpy="0 0 3.141592653589793" xyz="0 0 0"/>
      <geometry>
        <mesh filename="file://$(find ur3e_robotiq_description)/urdf/meshes/visual/finger.dae" scale="1.0 1.0 1.0"/>
      </geometry>
    </visual>
    <collision>
      <origin rpy="0 0 3.141592653589793" xyz="0 0 0"/>
      <geometry>
        <mesh filename="file://$(find ur3e_robotiq_description)/urdf/meshes/collision/finger_collision.dae" scale="1.0 1.0 1.0"/>
      </geometry>
    </collision>
    <inertial>
      <origin rpy="0 0 0" xyz="0 0 0"/>
      <mass value="0.03804"/>
      <inertia ixx="1E-9" ixy="0.0" ixz="0.0" iyy="1E-9" iyz="0.0" izz="1E-9"/>
    </inertial>
  </link>

  <joint name="robotiq_hande_end_joint" type="fixed">
    <origin rpy="0 0 0" xyz="0 0 0.1455"/>
    <parent link="robotiq_hande_link"/>
    <child link="robotiq_hande_end"/>
  </joint>

  <link name="robotiq_hande_end"/>

  <!-- links -  main UR3e serial chain -->
  <!-- base_link serves as the root of the robot's kinematic tree. It follows REP-103
        conventions (i.e., X+ forward, Y+ left, Z+ up).
        Since some kinematic solvers forbid having inertia values attached to a root link, we've
        added the base_link_inertia link that carries the visual, collision and inertia
        information.
    -->

  <link name="base_link"/>

  <link name="base_link_inertia">
    <visual>
      <origin rpy="0 0 3.141592653589793" xyz="0 0 0"/>
      <geometry>
        <mesh filename="file://$(find ur3e_robotiq_description)/urdf/meshes/visual/base.dae"/>
      </geometry>
    </visual>
    <collision>
      <origin rpy="0 0 3.141592653589793" xyz="0 0 0"/>
      <geometry>
        <mesh filename="file://$(find ur3e_robotiq_description)/urdf/meshes/collision/base.stl"/>
      </geometry>
    </collision>
    <inertial>
      <mass value="2.0"/>
      <origin rpy="0 0 0" xyz="0 0 0"/>
      <inertia ixx="0.0030531654454" ixy="0.0" ixz="0.0" iyy="0.0030531654454" iyz="0.0" izz="0.005625"/>
    </inertial>
  </link>

  <link name="shoulder_link">
    <visual>
      <origin rpy="0 0 3.141592653589793" xyz="0 0 0"/>
      <geometry>
        <mesh filename="file://$(find ur3e_robotiq_description)/urdf/meshes/visual/shoulder.dae"/>
      </geometry>
    </visual>
    <collision>
      <origin rpy="0 0 3.141592653589793" xyz="0 0 0"/>
      <geometry>
        <mesh filename="file://$(find ur3e_robotiq_description)/urdf/meshes/collision/shoulder.stl"/>
      </geometry>
    </collision>
    <inertial>
      <mass value="1.98"/>
      <origin rpy="1.570796326794897 0 0" xyz="0.0 0.0 -0.02"/>
      <inertia ixx="0.0027657" ixy="9.6e-06" ixz="-1.49e-05" iyy="0.0021501" iyz="0.0001873" izz="0.0025626"/>
    </inertial>
  </link>

  <link name="upper_arm_link">
    <visual>
      <origin rpy="1.5707963267948966 0 -1.5707963267948966" xyz="0 0 0.12"/>
      <geometry>
        <mesh filename="file://$(find ur3e_robotiq_description)/urdf/meshes/visual/upperarm.dae"/>
      </geometry>
    </visual>
    <collision>
      <origin rpy="1.5707963267948966 0 -1.5707963267948966" xyz="0 0 0.12"/>
      <geometry>
        <mesh filename="file://$(find ur3e_robotiq_description)/urdf/meshes/collision/upperarm.stl"/>
      </geometry>
    </collision>
    <inertial>
      <mass value="3.4445"/>
      <origin rpy="0 0 0" xyz="-0.11355 0.0 0.1157"/>
      <inertia ixx="0.0042623" ixy="-4.09e-05" ixz="-0.001496" iyy="0.0460284" iyz="-1.29e-05" izz="0.0448947"/>
    </inertial>
  </link>

  <link name="forearm_link">
    <visual>
      <origin rpy="1.5707963267948966 0 -1.5707963267948966" xyz="0 0 0.027"/>
      <geometry>
        <mesh filename="file://$(find ur3e_robotiq_description)/urdf/meshes/visual/forearm.dae"/>
      </geometry>
    </visual>
    <collision>
      <origin rpy="1.5707963267948966 0 -1.5707963267948966" xyz="0 0 0.027"/>
      <geometry>
        <mesh filename="file://$(find ur3e_robotiq_description)/urdf/meshes/collision/forearm.stl"/>
      </geometry>
    </collision>
    <inertial>
      <mass value="1.437"/>
      <origin rpy="0 0 0" xyz="-0.1632 0.0 0.0238"/>
      <inertia ixx="0.0010511" ixy="0.0" ixz="-3.31e-05" iyy="0.0113396" iyz="2.2e-06" izz="0.0110895"/>
    </inertial>
  </link>

  <link name="wrist_1_link">
    <visual>
      <origin rpy="1.5707963267948966 0 0" xyz="0 0 -0.104"/>
      <geometry>
        <mesh filename="file://$(find ur3e_robotiq_description)/urdf/meshes/visual/wrist1.dae"/>
      </geometry>
    </visual>
    <collision>
      <origin rpy="1.5707963267948966 0 0" xyz="0 0 -0.104"/>
      <geometry>
        <mesh filename="file://$(find ur3e_robotiq_description)/urdf/meshes/collision/wrist1.stl"/>
      </geometry>
    </collision>
    <inertial>
      <mass value="0.871"/>
      <origin rpy="1.570796326794897 0 0" xyz="0.0 -0.01 0.0"/>
      <inertia ixx="0.0008174" ixy="-5e-07" ixz="2.1e-06" iyy="0.0006844" iyz="6.17e-05" izz="0.0005497"/>
    </inertial>
  </link>

  <link name="wrist_2_link">
    <visual>
      <origin rpy="0 0 0" xyz="0 0 -0.08535"/>
      <geometry>
        <mesh filename="file://$(find ur3e_robotiq_description)/urdf/meshes/visual/wrist2.dae"/>
      </geometry>
    </visual>
    <collision>
      <origin rpy="0 0 0" xyz="0 0 -0.08535"/>
      <geometry>
        <mesh filename="file://$(find ur3e_robotiq_description)/urdf/meshes/collision/wrist2.stl"/>
      </geometry>
    </collision>
    <inertial>
      <mass value="0.805"/>
      <origin rpy="-1.570796326794897 0 0" xyz="0.0 0.01 0.0"/>
      <inertia ixx="0.0006059" ixy="-6e-07" ixz="-6e-07" iyy="0.0005837" iyz="-2.71e-05" izz="0.0003831"/>
    </inertial>
  </link>

  <link name="wrist_3_link">
    <visual>
      <origin rpy="1.5707963267948966 0 0" xyz="0 0 -0.0921"/>
      <geometry>
        <mesh filename="file://$(find ur3e_robotiq_description)/urdf/meshes/visual/wrist3.dae"/>
      </geometry>
    </visual>
    <collision>
      <origin rpy="1.5707963267948966 0 0" xyz="0 0 -0.0921"/>
      <geometry>
        <mesh filename="file://$(find ur3e_robotiq_description)/urdf/meshes/collision/wrist3.stl"/>
      </geometry>
    </collision>
    <inertial>
      <mass value="0.261"/>
      <origin rpy="0 0 0" xyz="0.0 0.0 -0.02"/>
      <inertia ixx="0.000108" ixy="-1e-07" ixz="-1e-07" iyy="0.0001086" iyz="-2e-07" izz="0.0001371"/>
    </inertial>
  </link>

  <!-- base_joint fixes base_link to the environment -->
  <joint name="base_joint" type="fixed">
    <origin rpy="0 0 0" xyz="0 0 .92"/>
    <parent link="world"/>
    <child link="base_link"/>
  </joint>

  <!-- joints - main serial chain -->
  <joint name="base_link-base_link_inertia" type="fixed">
    <parent link="base_link"/>
    <child link="base_link_inertia"/>
    <!-- 'base_link' is REP-103 aligned (so X+ forward), while the internal
           frames of the robot/controller have X+ pointing backwards.
           Use the joint between 'base_link' and 'base_link_inertia' (a dummy
           link/frame) to introduce the necessary rotation over Z (of pi rad).
      -->
    <origin rpy="0 0 3.141592653589793" xyz="0 0 0"/>
  </joint>

  <joint name="shoulder_pan_joint" type="revolute">
    <parent link="base_link_inertia"/>
    <child link="shoulder_link"/>
    <origin rpy="0 0 0" xyz="0 0 0.15185"/>
    <axis xyz="0 0 1"/>
    <limit effort="54.0" lower="-6.283185307179586" upper="6.283185307179586" velocity="3.141592653589793"/>
    <dynamics damping="0" friction="0"/>
  </joint>

  <joint name="shoulder_lift_joint" type="revolute">
    <parent link="shoulder_link"/>
    <child link="upper_arm_link"/>
    <origin rpy="1.570796327 0 0" xyz="0 0 0"/>
    <axis xyz="0 0 1"/>
    <limit effort="54.0" lower="-6.283185307179586" upper="6.283185307179586" velocity="3.141592653589793"/>
    <dynamics damping="0" friction="0"/>
  </joint>

  <joint name="elbow_joint" type="revolute">
    <parent link="upper_arm_link"/>
    <child link="forearm_link"/>
    <origin rpy="0 0 0" xyz="-0.24355 0 0"/>
    <axis xyz="0 0 1"/>
    <limit effort="28.0" lower="-3.141592653589793" upper="3.141592653589793" velocity="3.141592653589793"/>
    <dynamics damping="0" friction="0"/>
  </joint>

  <joint name="wrist_1_joint" type="revolute">
    <parent link="forearm_link"/>
    <child link="wrist_1_link"/>
    <origin rpy="0 0 0" xyz="-0.2132 0 0.13105"/>
    <axis xyz="0 0 1"/>
    <limit effort="9.0" lower="-6.283185307179586" upper="6.283185307179586" velocity="6.283185307179586"/>
    <dynamics damping="0" friction="0"/>
  </joint>

  <joint name="wrist_2_joint" type="revolute">
    <parent link="wrist_1_link"/>
    <child link="wrist_2_link"/>
    <origin rpy="1.570796327 0 0" xyz="0 -0.08535 -1.750557762378351e-11"/>
    <axis xyz="0 0 1"/>
    <limit effort="9.0" lower="-6.283185307179586" upper="6.283185307179586" velocity="6.283185307179586"/>
    <dynamics damping="0" friction="0"/>
  </joint>

  <joint name="wrist_3_joint" type="continuous">
    <parent link="wrist_2_link"/>
    <child link="wrist_3_link"/>
    <origin rpy="1.570796326589793 3.141592653589793 3.141592653589793" xyz="0 0.0921 -1.8890025766262e-11"/>
    <axis xyz="0 0 1"/>
    <limit effort="9.0" velocity="6.283185307179586"/>
    <dynamics damping="0" friction="0"/>
  </joint>

  <link name="ft_frame"/>

  <joint name="wrist_3_link-ft_frame" type="fixed">
    <parent link="wrist_3_link"/>
    <child link="ft_frame"/>
    <origin rpy="3.141592653589793 0 0" xyz="0 0 0"/>
  </joint>

  <!-- ROS-Industrial 'base' frame - base_link to UR 'Base' Coordinates transform -->
  <link name="base"/>

  <joint name="base_link-base_fixed_joint" type="fixed">
    <!-- Note the rotation over Z of pi radians - as base_link is REP-103
           aligned (i.e., has X+ forward, Y+ left and Z+ up), this is needed
           to correctly align 'base' with the 'Base' coordinate system of
           the UR controller.
      -->
    <origin rpy="0 0 3.141592653589793" xyz="0 0 0"/>
    <parent link="base_link"/>
    <child link="base"/>
  </joint>

  <!-- ROS-Industrial 'flange' frame - attachment point for EEF models -->
  <link name="flange"/>

  <joint name="wrist_3-flange" type="fixed">
    <parent link="wrist_3_link"/>
    <child link="flange"/>
    <origin rpy="0 -1.5707963267948966 -1.5707963267948966" xyz="0 0 0"/>
  </joint>

  <!-- ROS-Industrial 'tool0' frame - all-zeros tool frame -->
  <link name="tool0"/>

  <joint name="flange-tool0" type="fixed">
    <!-- default toolframe - X+ left, Y+ up, Z+ front -->
    <origin rpy="1.5707963267948966 0 1.5707963267948966" xyz="0 0 0"/>
    <parent link="flange"/>
    <child link="tool0"/>
  </joint>
</robot>
